Workbook

Sheet Dashboard
B2: Desempenho comercial | Vendas do 1º semestre de 2026
B3: Base fictícia de 240 pedidos (jan a jun/2026) | Projeto acadêmico | Autor: Kelton Almeida
B4: REGIÃO | D4: CATEGORIA | F4: CANAL
B5: Todos | D5: Todos | F5: Todos | H5: <- Escolha uma opção nos três filtros (caixas com borda azul).
B7: RECEITA TOTAL | D7: LUCRO TOTAL | F7: MARGEM (LUCRO / RECEITA) | H7: PEDIDOS | J7: TICKET MÉDIO
B8: =SUMIFS(Base_Vendas!$K$2:$K$241,Base_Vendas!$C$2:$C$241,Apoio!$B$4,Base_Vendas!$D$2:$D$241,Apoio!$B$5,Base_Vendas!$G$2:$G$241,Apoio!$B$6) -> 125841 | D8: =SUMIFS(Base_Vendas!$M$2:$M$241,Base_Vendas!$C$2:$C$241,Apoio!$B$4,Base_Vendas!$D$2:$D$241,Apoio!$B$5,Base_Vendas!$G$2:$G$241,Apoio!$B$6) -> 58183 | F8: =IFERROR(D8/B8,0) -> 0.46235329 | H8: =COUNTIFS(Base_Vendas!$C$2:$C$241,Apoio!$B$4,Base_Vendas!$D$2:$D$241,Apoio!$B$5,Base_Vendas!$G$2:$G$241,Apoio!$B$6) -> 240 | J8: =IFERROR(B8/H8,0) -> 524.3375
B9: =IFERROR(B8/SUM(Base_Vendas!$K$2:$K$241),0) -> 1 | D9: =IFERROR(D8/SUM(Base_Vendas!$M$2:$M$241),0) -> 1 | F9: =IFERROR(SUM(Base_Vendas!$M$2:$M$241)/SUM(Base_Vendas!$K$2:$K$241),0) -> 0.46235329 | H9: =IFERROR(H8/COUNTA(Base_Vendas!$A$2:$A$241),0) -> 1 | J9: =IFERROR(SUM(Base_Vendas!$K$2:$K$241)/COUNTA(Base_Vendas!$A$2:$A$241),0) -> 524.3375
B11: MELHOR MÊS | D11: REGIÃO LÍDER | F11: MAIOR MARGEM | H11: PRODUTO LÍDER | J11: CANAL LÍDER
B12: =Apoio!B67 -> Jun | D12: =Apoio!B68 -> Sudeste | F12: =Apoio!B69 -> Acessórios | H12: =Apoio!B70 -> Teclado Mecânico | J12: =Apoio!B71 -> Loja Online
B13: =Apoio!C67 -> 27510.4 | D13: =Apoio!C68 -> 50921.6 | F13: =Apoio!C69 -> 0.55163379 | H13: =Apoio!C70 -> 33986.4 | J13: =Apoio!C71 -> 55734.6
B45: Notas: (1) Os gráficos de região, categoria e canal não aplicam o próprio filtro, para permitir a comparação entre as opções.
B46: (2) Margem = lucro / receita (margem bruta, sem impostos, frete ou despesas).
B47: (3) Dados fictícios, sem informações pessoais; veja a aba Leia-me.

Sheet Leia-me
B2: Dashboard comercial | Vendas 1º semestre de 2026
B3: Documentação do projeto
B5: 1. Sobre o projeto
B6: Autor | C6: Kelton Almeida
B7: Disciplina / professor | C7: [preencher]
B8: Objetivo | C8: Acompanhar o desempenho de vendas de uma loja fictícia (receita, lucro, margem e pedidos) e permitir a comparação por região, categoria, canal, produto e mês.
B9: Perguntas respondidas | C9: Quais meses, regiões e produtos mais vendem? Quais categorias dão mais margem? Como cada canal contribui para a receita?
B11: 2. Dados
B12: Origem | C12: Base fictícia criada para fins didáticos. Não há clientes, lojas ou pessoas reais representados.
B13: Período e tamanho | C13: 240 pedidos entre 01/01/2026 e 30/06/2026. Cada linha da aba Base_Vendas é um pedido com um único produto.
B14: Tratamento aplicado | C14: Receita, custo total, lucro e mês agora são fórmulas na própria base (antes eram valores fixos), então qualquer correção na quantidade ou no preço atualiza tudo.
B16: 3. Proteção de dados pessoais (LGPD, Lei 13.709/2018)
B17: Minimização (art. 6º, III) | C17: A base não possui nome de cliente, CPF, e-mail, telefone ou endereço. Só entram os dados necessários para a análise comercial.
B18: Pseudonimização (art. 13, § 4º) | C18: Os nomes dos vendedores da versão anterior foram trocados por códigos (V01 a V06). A tabela de correspondência entre nome e código não foi mantida no arquivo.
B19: Sem avaliação individual | C19: O dashboard não ranqueia vendedores. Desempenho por pessoa seria um tratamento com mais risco e não é necessário para o objetivo do projeto.
B20: Se for usar dados reais | C20: Antes de publicar ou compartilhar, remova ou anonimize identificadores, defina a finalidade e a base legal do tratamento e restrinja o acesso ao arquivo.
B22: 4. Como usar
B23: Filtros | C23: Na aba Dashboard, escolha Região, Categoria e Canal nos menus (células com borda azul). Todos os indicadores e gráficos se atualizam.
B24: Gráficos comparativos | C24: Os gráficos de região, categoria e canal ignoram o próprio filtro, para que a comparação entre as opções continue visível.
B25: Abas | C25: Dashboard (visão final) | Leia-me (esta página) | Base_Vendas (dados) | Apoio (tabelas de cálculo e conferências automáticas).
B27: 5. Definição dos indicadores
B28: Receita | C28: Quantidade × preço unitário.
B29: Custo total | C29: Quantidade × custo unitário.
B30: Lucro | C30: Receita − custo total.
B31: Margem | C31: Lucro ÷ receita (margem bruta).
B32: Pedidos | C32: Número de linhas da base que atendem aos filtros.
B33: Ticket médio | C33: Receita ÷ número de pedidos.
B35: 6. Dicionário de dados (aba Base_Vendas)
B36: Pedido | C36: Número do pedido (único).
B37: Data | C37: Data da venda.
B38: Região | C38: Nordeste, Sudeste, Sul ou Centro-Oeste.
B39: Categoria / Produto | C39: 4 categorias e 12 produtos; cada produto pertence a uma única categoria.
B40: Vendedor | C40: Código pseudonimizado (V01 a V06).
B41: Canal | C41: Loja Online, Marketplace ou Loja Física.
B42: Quantidade, Preço e Custo unitário | C42: Valores informados (cabeçalho azul-escuro). Preço e custo são fixos por produto.
B43: Receita, Custo Total, Lucro, Mês Nº | C43: Calculados por fórmula (cabeçalho cinza).
B45: 7. Limitações
B46: Base pequena e fictícia | C46: Seis meses de dados simulados: os padrões observados não representam um negócio real nem permitem conclusões de sazonalidade.
B47: Margem bruta | C47: Não considera impostos, frete, comissões, devoluções ou despesas fixas.
B48: Validação | C48: A aba Apoio compara os KPIs com a soma dos meses e mostra OK ou DIVERGÊNCIA.

Sheet Base_Vendas
A1: Pedido | B1: Data | C1: Região | D1: Categoria | E1: Produto | F1: Vendedor | G1: Canal | H1: Quantidade | I1: Preço Unitário | J1: Custo Unitário | K1: Receita | L1: Custo Total | M1: Lucro | N1: Mês Nº
A2: 1001 | B2: 46186 | C2: Nordeste | D2: Esporte | E2: Garrafa Térmica | F2: V02 | G2: Marketplace | H2: 2 | I2: 89.9 | J2: 41 | K2: =H2*I2 -> 179.8 | L2: =H2*J2 -> 82 | M2: =K2-L2 -> 97.8 | N2: =MONTH(B2) -> 6
A3: 1002 | B3: 46196 | C3: Sul | D3: Eletrônicos | E3: Mouse Wireless | F3: V05 | G3: Loja Online | H3: 4 | I3: 99.9 | J3: 52 | K3: =H3*I3 -> 399.6 | L3: =H3*J3 -> 208 | M3: =K3-L3 -> 191.6 | N3: =MONTH(B3) -> 6
A4: 1003 | B4: 46078 | C4: Nordeste | D4: Eletrônicos | E4: Mouse Wireless | F4: V01 | G4: Marketplace | H4: 2 | I4: 99.9 | J4: 52 | K4: =H4*I4 -> 199.8 | L4: =H4*J4 -> 104 | M4: =K4-L4 -> 95.8 | N4: =MONTH(B4) -> 2
A5: 1004 | B5: 46162 | C5: Sudeste | D5: Acessórios | E5: Carregador Rápido | F5: V05 | G5: Marketplace | H5: 3 | I5: 129.9 | J5: 61 | K5: =H5*I5 -> 389.7 | L5: =H5*J5 -> 183 | M5: =K5-L5 -> 206.7 | N5: =MONTH(B5) -> 5
A6: 1005 | B6: 46063 | C6: Sul | D6: Esporte | E6: Kit Elástico | F6: V02 | G6: Loja Física | H6: 2 | I6: 69.9 | J6: 29 | K6: =H6*I6 -> 139.8 | L6: =H6*J6 -> 58 | M6: =K6-L6 -> 81.8 | N6: =MONTH(B6) -> 2
A7: 1006 | B7: 46109 | C7: Nordeste | D7: Acessórios | E7: Cabo USB-C | F7: V04 | G7: Marketplace | H7: 3 | I7: 39.9 | J7: 14 | K7: =H7*I7 -> 119.7 | L7: =H7*J7 -> 42 | M7: =K7-L7 -> 77.7 | N7: =MONTH(B7) -> 3
A8: 1007 | B8: 46034 | C8: Sul | D8: Eletrônicos | E8: Teclado Mecânico | F8: V03 | G8: Loja Online | H8: 1 | I8: 249.9 | J8: 155 | K8: =H8*I8 -> 249.9 | L8: =H8*J8 -> 155 | M8: =K8-L8 -> 94.9 | N8: =MONTH(B8) -> 1
A9: 1008 | B9: 46183 | C9: Sudeste | D9: Esporte | E9: Mochila Esportiva | F9: V01 | G9: Loja Online | H9: 2 | I9: 159.9 | J9: 86 | K9: =H9*I9 -> 319.8 | L9: =H9*J9 -> 172 | M9: =K9-L9 -> 147.8 | N9: =MONTH(B9) -> 6
A10: 1009 | B10: 46192 | C10: Nordeste | D10: Esporte | E10: Garrafa Térmica | F10: V02 | G10: Loja Física | H10: 7 | I10: 89.9 | J10: 41 | K10: =H10*I10 -> 629.3 | L10: =H10*J10 -> 287 | M10: =K10-L10 -> 342.3 | N10: =MONTH(B10) -> 6
A11: 1010 | B11: 46120 | C11: Nordeste | D11: Esporte | E11: Garrafa Térmica | F11: V04 | G11: Loja Online | H11: 3 | I11: 89.9 | J11: 41 | K11: =H11*I11 -> 269.7 | L11: =H11*J11 -> 123 | M11: =K11-L11 -> 146.7 | N11: =MONTH(B11) -> 4
A12: 1011 | B12: 46091 | C12: Sul | D12: Eletrônicos | E12: Mouse Wireless | F12: V02 | G12: Marketplace | H12: 6 | I12: 99.9 | J12: 52 | K12: =H12*I12 -> 599.4 | L12: =H12*J12 -> 312 | M12: =K12-L12 -> 287.4 | N12: =MONTH(B12) -> 3
A13: 1012 | B13: 46085 | C13: Nordeste | D13: Acessórios | E13: Suporte Notebook | F13: V01 | G13: Marketplace | H13: 6 | I13: 119.9 | J13: 55 | K13: =H13*I13 -> 719.4 | L13: =H13*J13 -> 330 | M13: =K13-L13 -> 389.4 | N13: =MONTH(B13) -> 3
... A241: 1240 | B241: 46196 | C241: Sul | D241: Acessórios | E241: Carregador Rápido | F241: V01 | G241: Marketplace | H241: 3 | I241: 129.9 | J241: 61 | K241: =H241*I241 -> 389.7 | L241: =H241*J241 -> 183 | M241: =K241-L241 -> 206.7 | N241: =MONTH(B241) -> 6

Sheet Apoio
A1: Apoio | tabelas de cálculo que alimentam o Dashboard
A2: Não é necessário editar esta aba. Tudo é recalculado a partir da Base_Vendas e dos filtros do Dashboard.
A3: Critérios dos filtros ("*" = todos)
A4: Região | B4: =IF(Dashboard!$B$5="Todos","*",Dashboard!$B$5) -> *
A5: Categoria | B5: =IF(Dashboard!$D$5="Todos","*",Dashboard!$D$5) -> *
A6: Canal | B6: =IF(Dashboard!$F$5="Todos","*",Dashboard!$F$5) -> *
A8: Evolução mensal (aplica os três filtros)
A9: Mês | B9: Nº | C9: Receita | D9: Lucro | E9: Pedidos
A10: Jan | B10: 1 | C10: =SUMIFS(Base_Vendas!$K$2:$K$241,Base_Vendas!$N$2:$N$241,$B10,Base_Vendas!$C$2:$C$241,$B$4,Base_Vendas!$D$2:$D$241,$B$5,Base_Vendas!$G$2:$G$241,$B$6) -> 25349.4 | D10: =SUMIFS(Base_Vendas!$M$2:$M$241,Base_Vendas!$N$2:$N$241,$B10,Base_Vendas!$C$2:$C$241,$B$4,Base_Vendas!$D$2:$D$241,$B$5,Base_Vendas!$G$2:$G$241,$B$6) -> 11797.4 | E10: =COUNTIFS(Base_Vendas!$N$2:$N$241,$B10,Base_Vendas!$C$2:$C$241,$B$4,Base_Vendas!$D$2:$D$241,$B$5,Base_Vendas!$G$2:$G$241,$B$6) -> 48
A11: Fev | B11: 2 | C11: =SUMIFS(Base_Vendas!$K$2:$K$241,Base_Vendas!$N$2:$N$241,$B11,Base_Vendas!$C$2:$C$241,$B$4,Base_Vendas!$D$2:$D$241,$B$5,Base_Vendas!$G$2:$G$241,$B$6) -> 12409.4 | D11: =SUMIFS(Base_Vendas!$M$2:$M$241,Base_Vendas!$N$2:$N$241,$B11,Base_Vendas!$C$2:$C$241,$B$4,Base_Vendas!$D$2:$D$241,$B$5,Base_Vendas!$G$2:$G$241,$B$6) -> 5987.4 | E11: =COUNTIFS(Base_Vendas!$N$2:$N$241,$B11,Base_Vendas!$C$2:$C$241,$B$4,Base_Vendas!$D$2:$D$241,$B$5,Base_Vendas!$G$2:$G$241,$B$6) -> 30
A12: Mar | B12: 3 | C12: =SUMIFS(Base_Vendas!$K$2:$K$241,Base_Vendas!$N$2:$N$241,$B12,Base_Vendas!$C$2:$C$241,$B$4,Base_Vendas!$D$2:$D$241,$B$5,Base_Vendas!$G$2:$G$241,$B$6) -> 17315.2 | D12: =SUMIFS(Base_Vendas!$M$2:$M$241,Base_Vendas!$N$2:$N$241,$B12,Base_Vendas!$C$2:$C$241,$B$4,Base_Vendas!$D$2:$D$241,$B$5,Base_Vendas!$G$2:$G$241,$B$6) -> 8360.2 | E12: =COUNTIFS(Base_Vendas!$N$2:$N$241,$B12,Base_Vendas!$C$2:$C$241,$B$4,Base_Vendas!$D$2:$D$241,$B$5,Base_Vendas!$G$2:$G$241,$B$6) -> 37
A13: Abr | B13: 4 | C13: =SUMIFS(Base_Vendas!$K$2:$K$241,Base_Vendas!$N$2:$N$241,$B13,Base_Vendas!$C$2:$C$241,$B$4,Base_Vendas!$D$2:$D$241,$B$5,Base_Vendas!$G$2:$G$241,$B$6) -> 21183.5 | D13: =SUMIFS(Base_Vendas!$M$2:$M$241,Base_Vendas!$N$2:$N$241,$B13,Base_Vendas!$C$2:$C$241,$B$4,Base_Vendas!$D$2:$D$241,$B$5,Base_Vendas!$G$2:$G$241,$B$6) -> 9699.5 | E13: =COUNTIFS(Base_Vendas!$N$2:$N$241,$B13,Base_Vendas!$C$2:$C$241,$B$4,Base_Vendas!$D$2:$D$241,$B$5,Base_Vendas!$G$2:$G$241,$B$6) -> 41
A14: Mai | B14: 5 | C14: =SUMIFS(Base_Vendas!$K$2:$K$241,Base_Vendas!$N$2:$N$241,$B14,Base_Vendas!$C$2:$C$241,$B$4,Base_Vendas!$D$2:$D$241,$B$5,Base_Vendas!$G$2:$G$241,$B$6) -> 22073.1 | D14: =SUMIFS(Base_Vendas!$M$2:$M$241,Base_Vendas!$N$2:$N$241,$B14,Base_Vendas!$C$2:$C$241,$B$4,Base_Vendas!$D$2:$D$241,$B$5,Base_Vendas!$G$2:$G$241,$B$6) -> 9920.1 | E14: =COUNTIFS(Base_Vendas!$N$2:$N$241,$B14,Base_Vendas!$C$2:$C$241,$B$4,Base_Vendas!$D$2:$D$241,$B$5,Base_Vendas!$G$2:$G$241,$B$6) -> 38
A15: Jun | B15: 6 | C15: =SUMIFS(Base_Vendas!$K$2:$K$241,Base_Vendas!$N$2:$N$241,$B15,Base_Vendas!$C$2:$C$241,$B$4,Base_Vendas!$D$2:$D$241,$B$5,Base_Vendas!$G$2:$G$241,$B$6) -> 27510.4 | D15: =SUMIFS(Base_Vendas!$M$2:$M$241,Base_Vendas!$N$2:$N$241,$B15,Base_Vendas!$C$2:$C$241,$B$4,Base_Vendas!$D$2:$D$241,$B$5,Base_Vendas!$G$2:$G$241,$B$6) -> 12418.4 | E15: =COUNTIFS(Base_Vendas!$N$2:$N$241,$B15,Base_Vendas!$C$2:$C$241,$B$4,Base_Vendas!$D$2:$D$241,$B$5,Base_Vendas!$G$2:$G$241,$B$6) -> 46
A18: Receita por região (ignora o filtro de Região)
A19: Região | B19: Receita
A20: Nordeste | B20: =SUMIFS(Base_Vendas!$K$2:$K$241,Base_Vendas!$C$2:$C$241,$A20,Base_Vendas!$D$2:$D$241,$B$5,Base_Vendas!$G$2:$G$241,$B$6) -> 33212.7
A21: Sudeste | B21: =SUMIFS(Base_Vendas!$K$2:$K$241,Base_Vendas!$C$2:$C$241,$A21,Base_Vendas!$D$2:$D$241,$B$5,Base_Vendas!$G$2:$G$241,$B$6) -> 50921.6
A22: Sul | B22: =SUMIFS(Base_Vendas!$K$2:$K$241,Base_Vendas!$C$2:$C$241,$A22,Base_Vendas!$D$2:$D$241,$B$5,Base_Vendas!$G$2:$G$241,$B$6) -> 20182.4
A23: Centro-Oeste | B23: =SUMIFS(Base_Vendas!$K$2:$K$241,Base_Vendas!$C$2:$C$241,$A23,Base_Vendas!$D$2:$D$241,$B$5,Base_Vendas!$G$2:$G$241,$B$6) -> 21524.3
A26: Margem por categoria (ignora o filtro de Categoria)
A27: Categoria | B27: Receita | C27: Lucro | D27: Margem
A28: Eletrônicos | B28: =SUMIFS(Base_Vendas!$K$2:$K$241,Base_Vendas!$D$2:$D$241,$A28,Base_Vendas!$C$2:$C$241,$B$4,Base_Vendas!$G$2:$G$241,$B$6) -> 54219.3 | C28: =SUMIFS(Base_Vendas!$M$2:$M$241,Base_Vendas!$D$2:$D$241,$A28,Base_Vendas!$C$2:$C$241,$B$4,Base_Vendas!$G$2:$G$241,$B$6) -> 21979.3 | D28: =IFERROR(C28/B28,0) -> 0.40537779
A29: Casa | B29: =SUMIFS(Base_Vendas!$K$2:$K$241,Base_Vendas!$D$2:$D$241,$A29,Base_Vendas!$C$2:$C$241,$B$4,Base_Vendas!$G$2:$G$241,$B$6) -> 21130.8 | C29: =SUMIFS(Base_Vendas!$M$2:$M$241,Base_Vendas!$D$2:$D$241,$A29,Base_Vendas!$C$2:$C$241,$B$4,Base_Vendas!$G$2:$G$241,$B$6) -> 9579.8 | D29: =IFERROR(C29/B29,0) -> 0.45335718
A30: Esporte | B30: =SUMIFS(Base_Vendas!$K$2:$K$241,Base_Vendas!$D$2:$D$241,$A30,Base_Vendas!$C$2:$C$241,$B$4,Base_Vendas!$G$2:$G$241,$B$6) -> 30261.9 | C30: =SUMIFS(Base_Vendas!$M$2:$M$241,Base_Vendas!$D$2:$D$241,$A30,Base_Vendas!$C$2:$C$241,$B$4,Base_Vendas!$G$2:$G$241,$B$6) -> 15464.9 | D30: =IFERROR(C30/B30,0) -> 0.51103533
A31: Acessórios | B31: =SUMIFS(Base_Vendas!$K$2:$K$241,Base_Vendas!$D$2:$D$241,$A31,Base_Vendas!$C$2:$C$241,$B$4,Base_Vendas!$G$2:$G$241,$B$6) -> 20229 | C31: =SUMIFS(Base_Vendas!$M$2:$M$241,Base_Vendas!$D$2:$D$241,$A31,Base_Vendas!$C$2:$C$241,$B$4,Base_Vendas!$G$2:$G$241,$B$6) -> 11159 | D31: =IFERROR(C31/B31,0) -> 0.55163379
A34: Receita por canal (ignora o filtro de Canal)
A35: Canal | B35: Receita
A36: Loja Online | B36: =SUMIFS(Base_Vendas!$K$2:$K$241,Base_Vendas!$G$2:$G$241,$A36,Base_Vendas!$C$2:$C$241,$B$4,Base_Vendas!$D$2:$D$241,$B$5) -> 55734.6
A37: Marketplace | B37: =SUMIFS(Base_Vendas!$K$2:$K$241,Base_Vendas!$G$2:$G$241,$A37,Base_Vendas!$C$2:$C$241,$B$4,Base_Vendas!$D$2:$D$241,$B$5) -> 39669.5
A38: Loja Física | B38: =SUMIFS(Base_Vendas!$K$2:$K$241,Base_Vendas!$G$2:$G$241,$A38,Base_Vendas!$C$2:$C$241,$B$4,Base_Vendas!$D$2:$D$241,$B$5) -> 30436.9
A40: Receita por produto (aplica os três filtros)
A41: Produto | B41: Categoria | C41: Receita | D41: Chave de desempate
A42: Cabo USB-C | B42: Acessórios | C42: =SUMIFS(Base_Vendas!$K$2:$K$241,Base_Vendas!$E$2:$E$241,$A42,Base_Vendas!$C$2:$C$241,$B$4,Base_Vendas!$D$2:$D$241,$B$5,Base_Vendas!$G$2:$G$241,$B$6) -> 2793 | D42: =C42+ROW()/1000000 -> 2793
A43: Cafeteira | B43: Casa | C43: =SUMIFS(Base_Vendas!$K$2:$K$241,Base_Vendas!$E$2:$E$241,$A43,Base_Vendas!$C$2:$C$241,$B$4,Base_Vendas!$D$2:$D$241,$B$5,Base_Vendas!$G$2:$G$241,$B$6) -> 12993.5 | D43: =C43+ROW()/1000000 -> 12993.5
A44: Carregador Rápido | B44: Acessórios | C44: =SUMIFS(Base_Vendas!$K$2:$K$241,Base_Vendas!$E$2:$E$241,$A44,Base_Vendas!$C$2:$C$241,$B$4,Base_Vendas!$D$2:$D$241,$B$5,Base_Vendas!$G$2:$G$241,$B$6) -> 8443.5 | D44: =C44+ROW()/1000000 -> 8443.5
A45: Fone Bluetooth | B45: Eletrônicos | C45: =SUMIFS(Base_Vendas!$K$2:$K$241,Base_Vendas!$E$2:$E$241,$A45,Base_Vendas!$C$2:$C$241,$B$4,Base_Vendas!$D$2:$D$241,$B$5,Base_Vendas!$G$2:$G$241,$B$6) -> 9443.7 | D45: =C45+ROW()/1000000 -> 9443.7
A46: Garrafa Térmica | B46: Esporte | C46: =SUMIFS(Base_Vendas!$K$2:$K$241,Base_Vendas!$E$2:$E$241,$A46,Base_Vendas!$C$2:$C$241,$B$4,Base_Vendas!$D$2:$D$241,$B$5,Base_Vendas!$G$2:$G$241,$B$6) -> 10518.3 | D46: =C46+ROW()/1000000 -> 10518.3
A47: Kit Elástico | B47: Esporte | C47: =SUMIFS(Base_Vendas!$K$2:$K$241,Base_Vendas!$E$2:$E$241,$A47,Base_Vendas!$C$2:$C$241,$B$4,Base_Vendas!$D$2:$D$241,$B$5,Base_Vendas!$G$2:$G$241,$B$6) -> 5032.8 | D47: =C47+ROW()/1000000 -> 5032.8
A48: Luminária LED | B48: Casa | C48: =SUMIFS(Base_Vendas!$K$2:$K$241,Base_Vendas!$E$2:$E$241,$A48,Base_Vendas!$C$2:$C$241,$B$4,Base_Vendas!$D$2:$D$241,$B$5,Base_Vendas!$G$2:$G$241,$B$6) -> 4794 | D48: =C48+ROW()/1000000 -> 4794
...
